<?xml version="1.0"?>
<sdf version="1.6">
  <model name="own">


  <plugin
    filename="ignition-gazebo-thruster-system"
    name="ignition::gazebo::systems::Thruster">
    <namespace>tethys</namespace>
    <joint_name>propeller_joint</joint_name>
    <thrust_coefficient>0.004422</thrust_coefficient>
    <fluid_density>1000</fluid_density>
    <propeller_diameter>0.2</propeller_diameter>
</plugin>

    <pose>0 0 0 0 0 0</pose>

    <link name="base_link">
        <pose>0 0 0 0 0 0</pose>
        <mass>0</mass>

    <sensor name="imu_sensor" type="imu">
	    <always_on>1</always_on>
	    <update_rate>1</update_rate>
	    <visualize>true</visualize>
	    <topic>imu</topic>
	     <frame_id>imu_link</frame_id>
	</sensor>
    </link>



  <link name="propeller">
      <pose>2 2 0 0 0 0</pose>
      
      <visual name="propeller_visual">
          <geometry>
              <box>
                  <size>0.1 0.1 0.1</size> <!-- Adjust box size as needed -->
              </box>
          </geometry>
          <material>
              <ambient>0.2 0.2 0.2 1</ambient>
              <diffuse>0.4 0.4 0.8 1</diffuse>
              <specular>0.5 0.5 0.5 1</specular>
          </material>
      </visual>
  </link>


      <include>
      <uri>file://bbccuu</uri>
      <name>bcu1</name>
      <pose>0 0 0 0 0 0</pose>
          <plugin
      filename="ignition-gazebo-buoyancy-engine-system"
      name="ignition::gazebo::systems::BuoyancyEngine">
      <link_name>body</link_name>
      <namespace>bcu1c</namespace>
      <min_volume>0.0</min_volume>
      <neutral_volume>0.002</neutral_volume>
      <default_volume>0.002</default_volume>
      <max_volume>0.009</max_volume>
      <max_inflation_rate>0.003</max_inflation_rate>
    </plugin>
      </include>
      <include>



      
      <uri>file://bbccuu</uri>
      <name>bcu2</name>
      <pose>0 4 0 0 0 0</pose>
               <plugin
      filename="ignition-gazebo-buoyancy-engine-system"
      name="ignition::gazebo::systems::BuoyancyEngine">
      <link_name>body</link_name>
      <namespace>bcu2c</namespace>
      <min_volume>0.0</min_volume>
      <neutral_volume>0.002</neutral_volume>
      <default_volume>0.002</default_volume>
      <max_volume>0.009</max_volume>
      <max_inflation_rate>0.003</max_inflation_rate>
    </plugin>
      </include>

            <include>
      <uri>file://bbccuu</uri>
      <name>bcu3</name>
      <pose>4 0 0 0 0 0</pose>
               <plugin
      filename="ignition-gazebo-buoyancy-engine-system"
      name="ignition::gazebo::systems::BuoyancyEngine">
      <link_name>body</link_name>
      <namespace>bcu3c</namespace>
      <min_volume>0.0</min_volume>
      <neutral_volume>0.002</neutral_volume>
      <default_volume>0.002</default_volume>
      <max_volume>0.009</max_volume>
      <max_inflation_rate>0.003</max_inflation_rate>
    </plugin>
      </include>

            <include>
      <uri>file://bbccuu</uri>
      <name>bcu4</name>
      <pose>4 4 0 0 0 0</pose>
         <plugin
      filename="ignition-gazebo-buoyancy-engine-system"
      name="ignition::gazebo::systems::BuoyancyEngine">
      <link_name>body</link_name>
      <namespace>bcu4c</namespace>
      <min_volume>0.0</min_volume>
      <neutral_volume>0.002</neutral_volume>
      <default_volume>0.002</default_volume>
      <max_volume>0.009</max_volume>
      <max_inflation_rate>0.003</max_inflation_rate>
    </plugin>
      </include>


 

          <!-- Fixed Joint -->
            <joint name='fixed_joint3' type='fixed'>
       <parent>base_link</parent>
      <child>bcu1</child>
      <pose>0 0 0 0 0 0</pose> <!-- Joint position is local to body1, since they're already separated -->
    </joint>
    <joint name='fixed_joint' type='fixed'>
      <parent>base_link</parent>
      <child>bcu2</child>
      <pose>0 0 0 0 0 0</pose> <!-- Joint position is local to body1, since they're already separated -->
    </joint>
    <joint name='fixed_joint1' type='fixed'>
      <parent>base_link</parent>
      <child>bcu3</child>
      <pose>0 0 0 0 0 0</pose> <!-- Joint position is local to body1, since they're already separated -->
    </joint>
        <joint name='fixed_joint2' type='fixed'>
      <parent>base_link</parent>
      <child>bcu4</child>
      <pose>0 0 0 0 0 0</pose> <!-- Joint position is local to body1, since they're already separated -->
    </joint>


    <joint name="propeller_joint" type="revolute">
      <pose>0 0 0 0 0 0</pose>
      <parent>base_link</parent>
      <child>propeller</child>
      <axis>
        <xyz>1 0 0</xyz>
        <limit>
          <lower>-1e+12</lower>
          <upper>1e+12</upper>
          <effort>-1</effort>
        </limit>
      </axis>
    </joint>
    
  </model>
</sdf>
