<?xml version="1.0" ?>
<sdf version="1.9">
  <model name="robotrr_v3_ap242_v2">



  <plugin
    filename="ignition-gazebo-thruster-system"
    name="ignition::gazebo::systems::Thruster">
    <namespace>tethys</namespace>
    <joint_name>umdrehung_1</joint_name>
    <thrust_coefficient>0.004422</thrust_coefficient>
    <fluid_density>1000</fluid_density>
    <propeller_diameter>0.2</propeller_diameter>
</plugin>
  <plugin
    filename="ignition-gazebo-thruster-system"
    name="ignition::gazebo::systems::Thruster">
    <namespace>tethys</namespace>
    <joint_name>umdrehung_2</joint_name>
    <thrust_coefficient>0.004422</thrust_coefficient>
    <fluid_density>1000</fluid_density>
    <propeller_diameter>0.2</propeller_diameter>
</plugin>
  <plugin
    filename="ignition-gazebo-thruster-system"
    name="ignition::gazebo::systems::Thruster">
    <namespace>tethys</namespace>
    <joint_name>umdrehung_3</joint_name>
    <thrust_coefficient>0.004422</thrust_coefficient>
    <fluid_density>1000</fluid_density>
    <propeller_diameter>0.2</propeller_diameter>
</plugin>
  <plugin
    filename="ignition-gazebo-thruster-system"
    name="ignition::gazebo::systems::Thruster">
    <namespace>tethys</namespace>
    <joint_name>umdrehung_4</joint_name>
    <thrust_coefficient>0.004422</thrust_coefficient>
    <fluid_density>1000</fluid_density>
    <propeller_diameter>0.2</propeller_diameter>
</plugin>


  <plugin name="ignition::gazebo::systems::JointStatePublisher" filename="ignition-gazebo-joint-state-publisher-system">
    <topic>/model/own/pose</topic>
    <joint_name>umdrehung_4</joint_name>
    <!-- Add more joints as needed -->
  </plugin>

  
<plugin filename="gz-sim-imu-system"
        name="gz::sim::systems::Imu">
</plugin>
<plugin
filename="ignition-gazebo-hydrodynamics-system"
name="ignition::gazebo::systems::Hydrodynamics">
    <link_name>base_link</link_name>
    <xDotU>-4.2</xDotU>
    <yDotV>-5.6</yDotV>
    <zDotW>-9.9</zDotW>
    <kDotP>0</kDotP>
    <mDotQ>-0.1</mDotQ>
    <nDotR>-0.1</nDotR>
<xUabsU>-65</xUabsU>  <!-- Quadratic damping in x direction [kg/m] -->
<xU>-1</xU>          <!-- Linear damping in x direction [kg] -->

<yVabsV>-6</yVabsV>  <!-- Quadratic damping in y direction [kg/m] -->
<yV>-1</yV>          <!-- Linear damping in y direction [kg] -->

<zWabsW>-35</zWabsW>  <!-- Quadratic damping in z direction [kg/m] -->
<zW>-1</zW>          <!-- Linear damping in z direction [kg] -->

<kPabsP>-40 </kPabsP>  <!-- Quadratic damping for roll [kg/m^2] -->
<kP>-100</kP>         <!-- Linear damping for roll [kg/m] -->

<mQabsQ>-40</mQabsQ>  <!-- Quadratic damping for pitch [kg/m^2] -->
<mQ>-1</mQ>         <!-- Linear damping for pitch [kg/m] -->

<nRabsR>-10</nRabsR> <!-- Quadratic damping for yaw [kg/m^2] -->
<nR> -1</nR>   
<default_current> 
0.0 0.0 0.0
</default_current>       <!-- Linear damping for yaw [kg/m] -->
</plugin>


    <link name="base_link">
    <sensor name="imu_sensor" type="imu">
	    <always_on>1</always_on>
	    <update_rate>30</update_rate>
	    <visualize>true</visualize>
	    <topic>/imu/data</topic>
	     <frame_id>imu_link</frame_id>
	      </sensor>

    <sensor name="navsat_sensor" type="navsat">
      <always_on>1</always_on>
      <update_rate>1</update_rate>
      <topic>navsat</topic>
      <noise type="gaussian">
        <mean>0.0</mean> <!-- Mean of the noise (no change) -->
        <stddev>9.0e-6</stddev> <!-- Standard deviation of noise (scale of variation) -->
      </noise>
    </sensor>

      <inertial>
        <pose>0.0 0.0 -0.08 0.0 0.0 0.0</pose>
        <mass>15</mass>
        <inertia>
          <ixx>2.0376757997506574</ixx>
          <ixy>4.3109103694207745e-05</ixy>
          <ixz>6.710900324836619e-05</ixz>
          <iyy>2.0378065661340696</iyy>
          <iyz>4.4045979259734326e-05</iyz>
          <izz>2.1555277012210636</izz>
        </inertia>
      </inertial>
      <visual name="base_link__k_rper1_visual">
        <geometry>
          <mesh>
            <scale>0.01 0.01 0.01</scale>
            <uri>meshes/base_link_1/k_rper1_visual.obj</uri>
          </mesh>
        </geometry>
      </visual>
      <collision name="base_link_1__k_rper1_collision">
        <pose relative_to="__model__">0.0 0.0 0.029923913436134004 -0.0 -1.5707963267948966 0</pose>
        <geometry>
          <box>
            <size>1 1 0.015</size>
          </box>
        </geometry>
      </collision>
    </link>
    <link name="thruster_1">
      <pose relative_to="__model__">-0.15740839067522924 0.33786941332852516 -0.08391442874603572 -2.9483811697419884 0.4478323969289321 0.8046336771011092</pose>
      <inertial>
        <pose>-0.09280026780692281 0.16330044965564414 -0.0382010430339387 -2.948381169741988 0.44783239692893195 0.8046336771011094</pose>
        <mass>0.00000001</mass>

      </inertial>
      <visual name="thruster_1__k_rper1_visual">
        <geometry>
          <mesh>
            <scale>0.01 0.01 0.01</scale>
            <uri>meshes/thruster_1/k_rper1_visual.obj</uri>
          </mesh>
        </geometry>
      </visual>

    </link>
    <link name="thruster_2">
      <pose relative_to="__model__">-0.18639497832762786 -0.32522488416731626 -0.07640208606787734 3.1415926535897922 -3.428276010253191e-15 3.141592653589788</pose>
      <inertial>
        <pose>-0.09280026780692278 0.16330044965564414 -0.038201043033938675 3.1415926535897922 3.4282760102531854e-15 3.141592653589788</pose>
        <mass>0.00000001</mass>

      </inertial>
      <visual name="thruster_2__k_rper1_visual">
        <geometry>
          <mesh>
            <scale>0.01 0.01 0.01</scale>
            <uri>meshes/thruster_2/k_rper1_visual.obj</uri>
          </mesh>
        </geometry>
      </visual>

    </link>
    <link name="thruster_3">
      <pose relative_to="__model__">0.3752627143267908 -0.015638188329460193 -0.07816060243133163 -3.033437135531454 0.21823451436745958 -1.176551951730111</pose>
      <inertial>
        <pose>-0.0928002678069227 0.163300449655644 -0.03820104303393867 2.8989930694609396 -0.01698837186572373 -1.186341171398918</pose>
        <mass>0.00000001</mass>

      </inertial>
      <visual name="thruster_3__k_rper1_visual">
        <geometry>
          <mesh>
            <scale>0.01 0.01 0.01</scale>
            <uri>meshes/thruster_3/k_rper1_visual.obj</uri>
          </mesh>
        </geometry>
      </visual>

    </link>
    <link name="thruster_4">
      <pose relative_to="__model__">0.05274666167984016 0.030323269282808266 0.39418346689423345 -0.9827937232473282 -0.44783239692893106 1.832595714594046</pose>
      <inertial>
        <pose>-0.09280026780692281 0.163300449655644 -0.038201043033938696 -0.7298884620629313 0.835351737579133 -1.9259427096895425</pose>
        <mass>0.00000001</mass>

      </inertial>
      <visual name="thruster_4__k_rper1_visual">
        <geometry>
          <mesh>
            <scale>0.01 0.01 0.01</scale>
            <uri>meshes/thruster_4/k_rper1_visual.obj</uri>
          </mesh>
        </geometry>
      </visual>
      <topic>/camera/rgb/image_raw</topic>

    </link>
    <!--       <pose relative_to="__model__">0 0 0 3.141592653589793 1.5708 0.0</pose> -->
    <link name="camera_1">
      <pose relative_to="__model__">0 0 -0.1 3.141592653589793 1.5708 0.0</pose>
      <sensor name="camera" type="camera">
      <camera>
          <horizontal_fov>1.047</horizontal_fov>
          <image>
              <width>1920</width>
              <height>1080</height>
          </image>
          <clip>
              <near>0.1</near>
              <far>100</far>
          </clip>
      </camera>
      <always_on>1</always_on>
      <update_rate>30</update_rate>
      <visualize>true</visualize>
      <topic>/cameraq/rgb/image_raw</topic>
  </sensor>
        <sensor name='gpu_lidar' type='gpu_lidar'>
          <always_on>1</always_on>
          <visualize>true</visualize>
          <topic>ultrasonic0</topic>
          <update_rate>100</update_rate>
          <lidar>
              <scan>
                  <vertical>
                    <samples>1</samples>
                    <resolution>1</resolution>
                    <min_angle>0.00</min_angle>
                    <max_angle>0.00002</max_angle>
                    <step>0.01</step>

                  </vertical>
              </scan>
          <range>
            <min>0.120000</min>
            <max>10</max>
            <resolution>0.015000</resolution>
          </range>
          <noise>
            <type>gaussian</type>
            <mean>0.0</mean>
            <stddev>0.01</stddev>
          </noise>
        </lidar>
    </sensor>

      <sensor name="wideangle_camera" type="wideanglecamera">
          <camera>
            <horizontal_fov>2</horizontal_fov>
            <image>
              <width>800</width>
              <height>600</height>
            </image>
            <clip>
              <near>0.1</near>
              <far>100</far>
            </clip>
            <!-- A new section named `lens`. -->
            <lens>
              <!-- type element is mandatory -->
              <type>custom</type>
              <!-- manually defined mapping function r = c1*f*fun(theta/c2 + c3) -->
              <!-- More information here: https://en.wikipedia.org/wiki/Fisheye_lens#Mapping_function -->
              <custom_function>
                <c1>1.05</c1>
                <!-- linear scaling -->
                <c2>4</c2>
                <!-- angle scaling -->
                <f>1.0</f>
                <!-- one more scaling parameter -->
                <fun>tan</fun>
                <!-- one of sin,tan,id -->
              </custom_function>
              <!-- if it is set to `true` your horizontal FOV will ramain as defined -->
              <!-- othervise it depends on lens type and custom function, if there is one -->
              <scale_to_hfov>true</scale_to_hfov>
              <!-- clip everything that is outside of this angle -->
              <cutoff_angle>3.1415</cutoff_angle>
              <!-- resolution of the cubemap texture, the highter it is - the sharper is your image -->
              <env_texture_size>512</env_texture_size>
            </lens>
          </camera>
          <always_on>1</always_on>
          <update_rate>30</update_rate>
          <topic>/camera/rgb/image_raw</topic>
        </sensor>
      <inertial>
        <pose>6.8615322235879956e-18 5.520228512852773e-18 -0.045076086563866184 -3.141592653589793 -0.0 0.0</pose>
        <mass>0.000000001</mass>

      </inertial>


    </link>


    <joint name="umdrehung_4" type="revolute">
      <pose relative_to="__model__">-3.552713678800501e-17 4.884981308350689e-17 0.19242391343613388 0.0 -0.0 0.0</pose>
      <parent>base_link</parent>
      <child>thruster_4</child>
      <axis>
         <xyz expressed_in="__model__">0.0 0.0 -1.0</xyz>
        <limit>
          <lower>-1e+12</lower>
          <upper>1e+12</upper>
          <effort>-1</effort>
          <velocity>-1</velocity>
        </limit>
      </axis>
    </joint>


    <joint name="umdrehung_1" type="revolute">
      <pose relative_to="__model__">-0.08414001376907834 0.14830044965564376 -0.028201043033938687 0.0 -0.0 0.0</pose>
      <parent>base_link</parent>
      <child>thruster_1</child>
      <axis>
        <xyz expressed_in="__model__">-0.4330127018922181 0.7500000000000001 -0.5000000000000011</xyz>
      </axis>

      <limit>
        <lower>-1e+12</lower>
        <upper>1e+12</upper>
        <effort>-1</effort>
        <velocity>-1</velocity>
      </limit>
    </joint>
    <joint name="umdrehung_2" type="revolute">
      <pose relative_to="__model__">-0.08493445648285966 -0.14692443451167297 -0.028201043033938805 0.0 -0.0 0.0</pose>
      <parent>base_link</parent>
      <child>thruster_2</child>
      <axis>
        <xyz expressed_in="__model__">-0.4330127018922222 -0.7499999999999982 -0.5000000000000002</xyz>
      </axis>
        <limit>
          <lower>-1e+12</lower>
          <upper>1e+12</upper>
          <effort>-1</effort>
          <velocity>-1</velocity>
        </limit>
    </joint>
    <joint name="umdrehung_3" type="revolute">
      <pose relative_to="__model__">0.17113501439224602 -8.881784197001253e-18 -0.028201043033938812 0.0 -0.0 0.0</pose>
      <parent>base_link</parent>
      <child>thruster_3</child>
      <axis>
        <xyz expressed_in="__model__">0.8660254037844385 0.0 -0.5000000000000003</xyz>
      </axis>

      <limit>
        <lower>-1e+12</lower>
        <upper>1e+12</upper>
        <effort>-1</effort>
        <velocity>-1</velocity>
      </limit>
    </joint>



    <joint name="starr_5" type="fixed">
      <pose relative_to="__model__">-1.7763568394002505e-17 -1.7763568394002505e-17 -0.0325760865638662 0.0 -0.0 0.0</pose>
      <parent>base_link</parent>
      <child>camera_1</child>
      <axis/>
    </joint>

  </model>
</sdf>
